Workbook

Sheet Storage
A1: Resource | B1: Zone | C1: Model | D1: New_Build | E1: Can_Retire | F1: Existing_Cap_MW | G1: Existing_Cap_MWh | H1: Max_Cap_MW | I1: Max_Cap_MWh | J1: Inv_Cost_per_MWyr | K1: Inv_Cost_per_MWhyr | L1: Fixed_OM_Cost_per_MWyr | M1: Fixed_OM_Cost_per_MWhyr | N1: Min_Cap_MW | O1: Min_Cap_MWh | P1: Var_OM_Cost_per_MWh | Q1: Var_OM_Cost_per_MWh_In | R1: Self_Disch | S1: Eff_Up | T1: Eff_Down | U1: Min_Duration | V1: Max_Duration | W1: Reg_Max | X1: Rsv_Max | Y1: Reg_Cost | Z1: Rsv_Cost | AA1: LDS | AB1: region | AC1: cluster | AD1: Resource_Type | AE1: MGA
A2: BANC_Li_Battery | B2: 5 | C2: 1 | D2: 0 | E2: 0 | F2: =INDEX(capacity!$H$2:$H$852,MATCH(A2,capacity!$A$2:$A$852,0)) -> 0 | G2: =INDEX(capacity!$M$2:$M$852,MATCH(A2,capacity!$A$2:$A$852,0)) -> 0 | H2: -1 | I2: -1 | J2: 0 | K2: 0 | L2: 0 | M2: 0 | N2: 0 | O2: 0 | P2: 0.0001 | Q2: 0 | R2: 0 | S2: 0.85 | T2: 1 | U2: 0 | V2: 9999 | W2: 0 | X2: 0 | Y2: 0.01 | Z2: 0.01 | AA2: 0 | AB2: LDWP | AC2: 1 | AD2: Storage | AE2: 0
A3: BANC_Li_Battery_New_Planned | B3: 5 | C3: 1 | D3: 0 | E3: 0 | F3: =INDEX(capacity!$H$2:$H$852,MATCH(A3,capacity!$A$2:$A$852,0)) -> 1348 | G3: =INDEX(capacity!$M$2:$M$852,MATCH(A3,capacity!$A$2:$A$852,0)) -> 5392 | H3: -1 | I3: -1 | J3: 0 | K3: 0 | L3: 0 | M3: 0 | N3: 0 | O3: 0 | P3: 0.0001 | Q3: 0 | R3: 0 | S3: 0.85 | T3: 1 | U3: 0 | V3: 9999 | W3: 0 | X3: 0 | Y3: 0.01 | Z3: 0.01 | AA3: 0 | AB3: LDWP | AC3: 1 | AD3: Storage | AE3: 0
A4: CAISO_Adiabatic_CAES_24hr | B4: 2 | C4: 1 | D4: 0 | E4: 0 | F4: =INDEX(capacity!$H$2:$H$852,MATCH(A4,capacity!$A$2:$A$852,0)) -> 200 | G4: =INDEX(capacity!$M$2:$M$852,MATCH(A4,capacity!$A$2:$A$852,0)) -> 4800 | H4: -1 | I4: -1 | J4: 0 | K4: 0 | L4: 0 | M4: 0 | N4: 0 | O4: 0 | P4: 0.0001 | Q4: 0 | R4: 0 | S4: 0.6 | T4: 1 | U4: 24 | V4: 24 | W4: 1 | X4: 1 | Y4: 0.01 | Z4: 0.01 | AA4: 0 | AB4: CAISO | AC4: 1 | AD4: Storage | AE4: 1
A5: CAISO_Flow_Battery_8hr_Dispatch | B5: 2 | C5: 1 | D5: 0 | E5: 0 | F5: =INDEX(capacity!$H$2:$H$852,MATCH(A5,capacity!$A$2:$A$852,0)) -> 308 | G5: =INDEX(capacity!$M$2:$M$852,MATCH(A5,capacity!$A$2:$A$852,0)) -> 2464 | H5: -1 | I5: -1 | J5: 0 | K5: 0 | L5: 0 | M5: 0 | N5: 0 | O5: 0 | P5: 0.0001 | Q5: 0 | R5: 0 | S5: 0.7 | T5: 1 | U5: 8 | V5: 8 | W5: 1 | X5: 1 | Y5: 0.01 | Z5: 0.01 | AA5: 0 | AB5: CAISO | AC5: 1 | AD5: Storage | AE5: 1
A6: CAISO_Generic_Energy_Storage_100hr | B6: 2 | C6: 1 | D6: 0 | E6: 0 | F6: =INDEX(capacity!$H$2:$H$852,MATCH(A6,capacity!$A$2:$A$852,0)) -> 0 | G6: =INDEX(capacity!$M$2:$M$852,MATCH(A6,capacity!$A$2:$A$852,0)) -> 0 | H6: -1 | I6: -1 | J6: 266271.73 | K6: 0 | L6: 55440.961080199995 | M6: 0 | N6: 0 | O6: 0 | P6: 0.0001 | Q6: 0 | R6: 0 | S6: 0.45 | T6: 1 | U6: 100 | V6: 100 | W6: 1 | X6: 1 | Y6: 0.01 | Z6: 0.01 | AA6: 0 | AB6: CAISO | AC6: 1 | AD6: Storage | AE6: 0
A7: CAISO_Generic_Energy_Storage_24hr | B7: 2 | C7: 1 | D7: 0 | E7: 0 | F7: =INDEX(capacity!$H$2:$H$852,MATCH(A7,capacity!$A$2:$A$852,0)) -> 0 | G7: =INDEX(capacity!$M$2:$M$852,MATCH(A7,capacity!$A$2:$A$852,0)) -> 0 | H7: -1 | I7: -1 | J7: 0 | K7: 0 | L7: 0 | M7: 0 | N7: 0 | O7: 0 | P7: 0.0001 | Q7: 0 | R7: 0 | S7: 0.6 | T7: 1 | U7: 24 | V7: 24 | W7: 1 | X7: 1 | Y7: 0.01 | Z7: 0.01 | AA7: 0 | AB7: CAISO | AC7: 1 | AD7: Storage | AE7: 0
A8: CAISO_Li_Battery_4hr_Baseline | B8: 2 | C8: 1 | D8: 0 | E8: 0 | F8: =INDEX(capacity!$H$2:$H$852,MATCH(A8,capacity!$A$2:$A$852,0)) -> 8964.69 | G8: =INDEX(capacity!$M$2:$M$852,MATCH(A8,capacity!$A$2:$A$852,0)) -> 34846.33 | H8: -1 | I8: -1 | J8: 0 | K8: 0 | L8: 0 | M8: 0 | N8: 0 | O8: 0 | P8: 0.0001 | Q8: 0 | R8: 0 | S8: 0.85 | T8: 1 | U8: 0 | V8: 9999 | W8: 1 | X8: 1 | Y8: 0.01 | Z8: 0.01 | AA8: 0 | AB8: CAISO | AC8: 1 | AD8: Storage | AE8: 0
A9: CAISO_Li_Battery_4hr_Dispatch | B9: 2 | C9: 1 | D9: 0 | E9: 0 | F9: =INDEX(capacity!$H$2:$H$852,MATCH(A9,capacity!$A$2:$A$852,0)) -> 15707 | G9: =INDEX(capacity!$M$2:$M$852,MATCH(A9,capacity!$A$2:$A$852,0)) -> 62828 | H9: -1 | I9: -1 | J9: 0 | K9: 0 | L9: 0 | M9: 0 | N9: 0 | O9: 0 | P9: 0.0001 | Q9: 0 | R9: 0 | S9: 0.85 | T9: 1 | U9: 4 | V9: 4 | W9: 1 | X9: 1 | Y9: 0.01 | Z9: 0.01 | AA9: 0 | AB9: CAISO | AC9: 1 | AD9: Storage | AE9: 1
A10: CAISO_Li_Battery_8hr_Baseline | B10: 2 | C10: 1 | D10: 0 | E10: 0 | F10: =INDEX(capacity!$H$2:$H$852,MATCH(A10,capacity!$A$2:$A$852,0)) -> 210 | G10: =INDEX(capacity!$M$2:$M$852,MATCH(A10,capacity!$A$2:$A$852,0)) -> 2028 | H10: -1 | I10: -1 | J10: 0 | K10: 0 | L10: 0 | M10: 0 | N10: 0 | O10: 0 | P10: 0.0001 | Q10: 0 | R10: 0 | S10: 0.85 | T10: 1 | U10: 0 | V10: 9999 | W10: 1 | X10: 1 | Y10: 0.01 | Z10: 0.01 | AA10: 0 | AB10: CAISO | AC10: 1 | AD10: Storage | AE10: 0
A11: CAISO_Li_Battery_8hr_Dispatch | B11: 2 | C11: 1 | D11: 0 | E11: 0 | F11: =INDEX(capacity!$H$2:$H$852,MATCH(A11,capacity!$A$2:$A$852,0)) -> 2834 | G11: =INDEX(capacity!$M$2:$M$852,MATCH(A11,capacity!$A$2:$A$852,0)) -> 22672 | H11: -1 | I11: -1 | J11: 0 | K11: 0 | L11: 0 | M11: 0 | N11: 0 | O11: 0 | P11: 0.0001 | Q11: 0 | R11: 0 | S11: 0.85 | T11: 1 | U11: 8 | V11: 8 | W11: 1 | X11: 1 | Y11: 0.01 | Z11: 0.01 | AA11: 0 | AB11: CAISO | AC11: 1 | AD11: Storage | AE11: 1
A12: CAISO_New_Pumped_Storage_12hr | B12: 2 | C12: 1 | D12: 0 | E12: 0 | F12: =INDEX(capacity!$H$2:$H$852,MATCH(A12,capacity!$A$2:$A$852,0)) -> 477 | G12: =INDEX(capacity!$M$2:$M$852,MATCH(A12,capacity!$A$2:$A$852,0)) -> 5724 | H12: -1 | I12: -1 | J12: 0 | K12: 0 | L12: 0 | M12: 0 | N12: 0 | O12: 0 | P12: 0.0001 | Q12: 0 | R12: 0 | S12: 0.81 | T12: 1 | U12: 12 | V12: 12 | W12: 1 | X12: 1 | Y12: 0.01 | Z12: 0.01 | AA12: 0 | AB12: CAISO | AC12: 1 | AD12: Storage | AE12: 1
A13: CAISO_Pumped_Hydro | B13: 2 | C13: 1 | D13: 0 | E13: 0 | F13: =INDEX(capacity!$H$2:$H$852,MATCH(A13,capacity!$A$2:$A$852,0)) -> 1483.2 | G13: =INDEX(capacity!$M$2:$M$852,MATCH(A13,capacity!$A$2:$A$852,0)) -> 189725.8 | H13: -1 | I13: -1 | J13: 0 | K13: 0 | L13: 0 | M13: 0 | N13: 0 | O13: 0 | P13: 0.0001 | Q13: 0 | R13: 0 | S13: 0.649 | T13: 1 | U13: 0 | V13: 9999 | W13: 1 | X13: 1 | Y13: 0.01 | Z13: 0.01 | AA13: 0 | AB13: CAISO | AC13: 1 | AD13: Storage | AE13: 0
A14: IID_Li_Battery | B14: 4 | C14: 1 | D14: 0 | E14: 0 | F14: =INDEX(capacity!$H$2:$H$852,MATCH(A14,capacity!$A$2:$A$852,0)) -> 231 | G14: =INDEX(capacity!$M$2:$M$852,MATCH(A14,capacity!$A$2:$A$852,0)) -> 924 | H14: -1 | I14: -1 | J14: 0 | K14: 0 | L14: 0 | M14: 0 | N14: 0 | O14: 0 | P14: 0.0001 | Q14: 0 | R14: 0 | S14: 0.85 | T14: 1 | U14: 0 | V14: 9999 | W14: 0 | X14: 0 | Y14: 0.01 | Z14: 0.01 | AA14: 0 | AB14: IID | AC14: 1 | AD14: Storage | AE14: 0
A15: IID_Li_Battery_New_Planned | B15: 4 | C15: 1 | D15: 0 | E15: 0 | F15: =INDEX(capacity!$H$2:$H$852,MATCH(A15,capacity!$A$2:$A$852,0)) -> 0 | G15: =INDEX(capacity!$M$2:$M$852,MATCH(A15,capacity!$A$2:$A$852,0)) -> 0 | H15: -1 | I15: -1 | J15: 0 | K15: 0 | L15: 0 | M15: 0 | N15: 0 | O15: 0 | P15: 0.0001 | Q15: 0 | R15: 0 | S15: 0.85 | T15: 1 | U15: 0 | V15: 9999 | W15: 0 | X15: 0 | Y15: 0.01 | Z15: 0.01 | AA15: 0 | AB15: IID | AC15: 1 | AD15: Storage | AE15: 0
A16: LDWP_Li_Battery | B16: 5 | C16: 1 | D16: 0 | E16: 0 | F16: =INDEX(capacity!$H$2:$H$852,MATCH(A16,capacity!$A$2:$A$852,0)) -> 695 | G16: =INDEX(capacity!$M$2:$M$852,MATCH(A16,capacity!$A$2:$A$852,0)) -> 2480 | H16: -1 | I16: -1 | J16: 0 | K16: 0 | L16: 0 | M16: 0 | N16: 0 | O16: 0 | P16: 0.0001 | Q16: 0 | R16: 0 | S16: 0.85 | T16: 1 | U16: 0 | V16: 9999 | W16: 0 | X16: 0 | Y16: 0.01 | Z16: 0.01 | AA16: 0 | AB16: LDWP | AC16: 1 | AD16: Storage | AE16: 0
A17: LDWP_Li_Battery_New_Planned | B17: 5 | C17: 1 | D17: 0 | E17: 0 | F17: =INDEX(capacity!$H$2:$H$852,MATCH(A17,capacity!$A$2:$A$852,0)) -> 1255 | G17: =INDEX(capacity!$M$2:$M$852,MATCH(A17,capacity!$A$2:$A$852,0)) -> 5020 | H17: -1 | I17: -1 | J17: 0 | K17: 0 | L17: 0 | M17: 0 | N17: 0 | O17: 0 | P17: 0.0001 | Q17: 0 | R17: 0 | S17: 0.85 | T17: 1 | U17: 0 | V17: 9999 | W17: 0 | X17: 0 | Y17: 0.01 | Z17: 0.01 | AA17: 0 | AB17: LDWP | AC17: 1 | AD17: Storage | AE17: 0
A18: LDWP_Pumped_Hydro | B18: 5 | C18: 1 | D18: 0 | E18: 0 | F18: =INDEX(capacity!$H$2:$H$852,MATCH(A18,capacity!$A$2:$A$852,0)) -> 1460 | G18: =INDEX(capacity!$M$2:$M$852,MATCH(A18,capacity!$A$2:$A$852,0)) -> 34464.274 | H18: -1 | I18: -1 | J18: 0 | K18: 0 | L18: 0 | M18: 0 | N18: 0 | O18: 0 | P18: 0.0001 | Q18: 0 | R18: 0 | S18: 0.75 | T18: 1 | U18: 0 | V18: 9999 | W18: 0 | X18: 0 | Y18: 0.01 | Z18: 0.01 | AA18: 0 | AB18: LDWP | AC18: 1 | AD18: Storage | AE18: 0
... A24: SW_Pumped_Hydro | B24: 7 | C24: 1 | D24: 0 | E24: 0 | F24: =INDEX(capacity!$H$2:$H$852,MATCH(A24,capacity!$A$2:$A$852,0)) -> 969.6 | G24: =INDEX(capacity!$M$2:$M$852,MATCH(A24,capacity!$A$2:$A$852,0)) -> 129054 | H24: -1 | I24: -1 | J24: 0 | K24: 0 | L24: 0 | M24: 0 | N24: 0 | O24: 0 | P24: 0.0001 | Q24: 0 | R24: 0 | S24: 0.625 | T24: 1 | U24: 0 | V24: 9999 | W24: 0 | X24: 0 | Y24: 0.01 | Z24: 0.01 | AA24: 0 | AB24: SW | AC24: 1 | AD24: Storage | AE24: 0

Sheet capacity
A1: Resource | B1: Zone | C1: Retrofit_Id | D1: StartCap | E1: RetCap | F1: RetroCap | G1: NewCap | H1: EndCap | I1: CapacityConstraintDual | J1: StartEnergyCap | K1: RetEnergyCap | L1: NewEnergyCap | M1: EndEnergyCap | N1: StartChargeCap | O1: RetChargeCap | P1: NewChargeCap | Q1: EndChargeCap
A2: BANC_Hydro | B2: 1 | C2: None | D2: 2040 | E2: 0 | F2: 0 | G2: 0 | H2: 2040 | I2: 0 | J2: 0 | K2: 0 | L2: 0 | M2: 0 | N2: 0 | O2: 0 | P2: 0 | Q2: 0
A3: CAISO_Hydro | B3: 2 | C3: None | D3: 6661.9068 | E3: 0 | F3: 0 | G3: 0 | H3: 6661.9068 | I3: 0 | J3: 0 | K3: 0 | L3: 0 | M3: 0 | N3: 0 | O3: 0 | P3: 0 | Q3: 0
A4: LDWP_Hydro | B4: 5 | C4: None | D4: 1005.4572 | E4: 0 | F4: 0 | G4: 0 | H4: 1005.4572 | I4: 0 | J4: 0 | K4: 0 | L4: 0 | M4: 0 | N4: 0 | O4: 0 | P4: 0 | Q4: 0
A5: NW_Hydro | B5: 6 | C5: None | D5: 20527.894 | E5: 0 | F5: 0 | G5: 0 | H5: 20527.894 | I5: 0 | J5: 0 | K5: 0 | L5: 0 | M5: 0 | N5: 0 | O5: 0 | P5: 0 | Q5: 0
A6: NW_Hydro_for_CAISO | B6: 3 | C6: None | D6: 1860.9395 | E6: 0 | F6: 0 | G6: 0 | H6: 1860.9395 | I6: 0 | J6: 0 | K6: 0 | L6: 0 | M6: 0 | N6: 0 | O6: 0 | P6: 0 | Q6: 0
A7: SW_Hydro | B7: 7 | C7: None | D7: 2594.1218 | E7: 0 | F7: 0 | G7: 0 | H7: 2594.1218 | I7: 0 | J7: 0 | K7: 0 | L7: 0 | M7: 0 | N7: 0 | O7: 0 | P7: 0 | Q7: 0
A8: BANC_Biogas | B8: 1 | C8: None | D8: 17.5 | E8: 0 | F8: 0 | G8: 0 | H8: 17.5 | I8: 0 | J8: 0 | K8: 0 | L8: 0 | M8: 0 | N8: 0 | O8: 0 | P8: 0 | Q8: 0
A9: BANC_Biomass | B9: 1 | C9: None | D9: 0.69 | E9: 0 | F9: 0 | G9: 0 | H9: 0.69 | I9: 0 | J9: 0 | K9: 0 | L9: 0 | M9: 0 | N9: 0 | O9: 0 | P9: 0 | Q9: 0
A10: BANC_CCGT1 | B10: 1 | C10: None | D10: 847.3 | E10: 0 | F10: 0 | G10: 0 | H10: 847.3 | I10: 0 | J10: 0 | K10: 0 | L10: 0 | M10: 0 | N10: 0 | O10: 0 | P10: 0 | Q10: 0
A11: BANC_CCGT2 | B11: 1 | C11: None | D11: 674.2 | E11: 0 | F11: 0 | G11: 0 | H11: 674.2 | I11: 0 | J11: 0 | K11: 0 | L11: 0 | M11: 0 | N11: 0 | O11: 0 | P11: 0 | Q11: 0
A12: BANC_Geothermal | B12: 1 | C12: None | D12: 69.5 | E12: 0 | F12: 0 | G12: 0 | H12: 69.5 | I12: 0 | J12: 0 | K12: 0 | L12: 0 | M12: 0 | N12: 0 | O12: 0 | P12: 0 | Q12: 0
A13: BANC_Geothermal_New_Planned | B13: 1 | C13: None | D13: 215 | E13: 0 | F13: 0 | G13: 0 | H13: 215 | I13: 0 | J13: 0 | K13: 0 | L13: 0 | M13: 0 | N13: 0 | O13: 0 | P13: 0 | Q13: 0
... A88: Utah_Geothermal | B88: 2 | C88: None | D88: 0 | E88: 0 | F88: 0 | G88: 0 | H88: 0 | I88: 0 | J88: 0 | K88: 0 | L88: 0 | M88: 0 | N88: 0 | O88: 0 | P88: 0 | Q88: 0
A89: Arizona_Solar | B89: 2 | C89: None | D89: 0 | E89: 0 | F89: 0 | G89: 13809.287175333873 | H89: 13809.287175333873 | I89: 0 | J89: 0 | K89: 0 | L89: 0 | M89: 0 | N89: 0 | O89: 0 | P89: 0 | Q89: 0
A90: BANC_Solar | B90: 1 | C90: None | D90: 488.2 | E90: 0 | F90: 0 | G90: 0 | H90: 488.2 | I90: 0 | J90: 0 | K90: 0 | L90: 0 | M90: 0 | N90: 0 | O90: 0 | P90: 0 | Q90: 0
A91: BANC_Solar_New_Planned | B91: 1 | C91: None | D91: 3625 | E91: 0 | F91: 0 | G91: 0 | H91: 3625 | I91: 0 | J91: 0 | K91: 0 | L91: 0 | M91: 0 | N91: 0 | O91: 0 | P91: 0 | Q91: 0
A92: BANC_Wind | B92: 1 | C92: None | D92: 429.98 | E92: 0 | F92: 0 | G92: 0 | H92: 429.98 | I92: 0 | J92: 0 | K92: 0 | L92: 0 | M92: 0 | N92: 0 | O92: 0 | P92: 0 | Q92: 0
A93: BANC_Wind_New_Planned | B93: 1 | C93: None | D93: 1734 | E93: 0 | F93: 0 | G93: 0 | H93: 1734 | I93: 0 | J93: 0 | K93: 0 | L93: 0 | M93: 0 | N93: 0 | O93: 0 | P93: 0 | Q93: 0
A94: Baja_California_Wind | B94: 2 | C94: None | D94: 0 | E94: 0 | F94: 0 | G94: 2472.82 | H94: 2472.82 | I94: 0 | J94: 0 | K94: 0 | L94: 0 | M94: 0 | N94: 0 | O94: 0 | P94: 0 | Q94: 0
A95: CAISO_Solar | B95: 2 | C95: None | D95: 19037.3 | E95: 0 | F95: 0 | G95: 0 | H95: 19037.3 | I95: 0 | J95: 0 | K95: 0 | L95: 0 | M95: 0 | N95: 0 | O95: 0 | P95: 0 | Q95: 0
A96: CAISO_Wind | B96: 2 | C96: None | D96: 7789.09 | E96: 0 | F96: 0 | G96: 0 | H96: 7789.09 | I96: 0 | J96: 0 | K96: 0 | L96: 0 | M96: 0 | N96: 0 | O96: 0 | P96: 0 | Q96: 0
A97: Cape_Mendocino_Offshore_Wind | B97: 2 | C97: None | D97: 0 | E97: 0 | F97: 0 | G97: 0 | H97: 0 | I97: 0 | J97: 0 | K97: 0 | L97: 0 | M97: 0 | N97: 0 | O97: 0 | P97: 0 | Q97: 0
A98: Central_Valley_North_Los_Banos_Wind | B98: 2 | C98: None | D98: 0 | E98: 0 | F98: 0 | G98: 32 | H98: 32 | I98: 0 | J98: 0 | K98: 0 | L98: 0 | M98: 0 | N98: 0 | O98: 0 | P98: 0 | Q98: 0
A99: Del_Norte_Offshore_Wind | B99: 2 | C99: None | D99: 0 | E99: 0 | F99: 0 | G99: 0 | H99: 0 | I99: 0 | J99: 0 | K99: 0 | L99: 0 | M99: 0 | N99: 0 | O99: 0 | P99: 0 | Q99: 0
A100: Distributed_Solar | B100: 2 | C100: None | D100: 0 | E100: 0 | F100: 0 | G100: 0 | H100: 0 | I100: 0 | J100: 0 | K100: 0 | L100: 0 | M100: 0 | N100: 0 | O100: 0 | P100: 0 | Q100: 0
A101: Greater_Imperial_Solar | B101: 2 | C101: None | D101: 0 | E101: 0 | F101: 0 | G101: 39 | H101: 39 | I101: 0 | J101: 0 | K101: 0 | L101: 0 | M101: 0 | N101: 0 | O101: 0 | P101: 0 | Q101: 0
A102: Greater_Imperial_Wind | B102: 2 | C102: None | D102: 0 | E102: 0 | F102: 0 | G102: 133.20504 | H102: 133.20504 | I102: 0 | J102: 0 | K102: 0 | L102: 0 | M102: 0 | N102: 0 | O102: 0 | P102: 0 | Q102: 0
A103: Greater_Kramer_Solar | B103: 2 | C103: None | D103: 0 | E103: 0 | F103: 0 | G103: 1423.3766233766235 | H103: 1423.3766233766235 | I103: 0 | J103: 0 | K103: 0 | L103: 0 | M103: 0 | N103: 0 | O103: 0 | P103: 0 | Q103: 0
A104: Greater_LA_Solar | B104: 2 | C104: None | D104: 0 | E104: 0 | F104: 0 | G104: 0 | H104: 0 | I104: 0 | J104: 0 | K104: 0 | L104: 0 | M104: 0 | N104: 0 | O104: 0 | P104: 0 | Q104: 0
A105: Humboldt_Bay_Offshore_Wind | B105: 2 | C105: None | D105: 0 | E105: 0 | F105: 0 | G105: 0 | H105: 0 | I105: 0 | J105: 0 | K105: 0 | L105: 0 | M105: 0 | N105: 0 | O105: 0 | P105: 0 | Q105: 0
A106: IID_Solar | B106: 4 | C106: None | D106: 545.8 | E106: 0 | F106: 0 | G106: 0 | H106: 545.8 | I106: 0 | J106: 0 | K106: 0 | L106: 0 | M106: 0 | N106: 0 | O106: 0 | P106: 0 | Q106: 0
A107: IID_Solar_New_Planned | B107: 4 | C107: None | D107: 435 | E107: 0 | F107: 0 | G107: 0 | H107: 435 | I107: 0 | J107: 0 | K107: 0 | L107: 0 | M107: 0 | N107: 0 | O107: 0 | P107: 0 | Q107: 0
A108: Idaho_Wind | B108: 2 | C108: None | D108: 0 | E108: 0 | F108: 0 | G108: 300 | H108: 300 | I108: 0 | J108: 0 | K108: 0 | L108: 0 | M108: 0 | N108: 0 | O108: 0 | P108: 0 | Q108: 0
A109: LDWP_Solar | B109: 5 | C109: None | D109: 2462.12 | E109: 0 | F109: 0 | G109: 0 | H109: 2462.12 | I109: 0 | J109: 0 | K109: 0 | L109: 0 | M109: 0 | N109: 0 | O109: 0 | P109: 0 | Q109: 0
A110: LDWP_Solar_New_Planned | B110: 5 | C110: None | D110: 1790 | E110: 0 | F110: 0 | G110: 0 | H110: 1790 | I110: 0 | J110: 0 | K110: 0 | L110: 0 | M110: 0 | N110: 0 | O110: 0 | P110: 0 | Q110: 0
A111: LDWP_Wind | B111: 5 | C111: None | D111: 423.5 | E111: 0 | F111: 0 | G111: 0 | H111: 423.5 | I111: 0 | J111: 0 | K111: 0 | L111: 0 | M111: 0 | N111: 0 | O111: 0 | P111: 0 | Q111: 0
A112: LDWP_Wind_New_Planned | B112: 5 | C112: None | D112: 2750 | E112: 0 | F112: 0 | G112: 0 | H112: 2750 | I112: 0 | J112: 0 | K112: 0 | L112: 0 | M112: 0 | N112: 0 | O112: 0 | P112: 0 | Q112: 0
A113: Morro_Bay_Offshore_Wind | B113: 2 | C113: None | D113: 0 | E113: 0 | F113: 0 | G113: 4531 | H113: 4531 | I113: 0 | J113: 0 | K113: 0 | L113: 0 | M113: 0 | N113: 0 | O113: 0 | P113: 0 | Q113: 0
A114: NW_Solar | B114: 6 | C114: None | D114: 3065.47 | E114: 0 | F114: 0 | G114: 0 | H114: 3065.47 | I114: 0 | J114: 0 | K114: 0 | L114: 0 | M114: 0 | N114: 0 | O114: 0 | P114: 0 | Q114: 0
...
